Workbook

Sheet DB DQS100
A1: Num. Articolo | B1: Num. parte | C1: Descrizione | D1: Forma grezzo | E1: Dimensione 1 Grezzo | F1: Dimensione 2 Grezzo | G1: Dimensione 3 Grezzo | H1: Quantità | I1: Peso [g] | J1: Materiale | K1: Costo[€] | L1: Colonna1 | M1: Quantità per 100 pompe
A2: 1 | B2: P001-025-001B | C2: CORPO FLUIDO | D2: Lastra | E2: 230 | F2: 220 | G2: 130 | H2: 1 | I2: 10061.51 | J2: PTFE generico | K2: =(( I2/1000 )*'P001-025-001B'!$F$1 + SUM('P001-025-001B'!$G$4:'P001-025-001B'!$G$30))*H2 -> 10091.51 | L2: m | M2: =150*Tabella1[[#This Row],[Quantità]] -> 150
A3: 2 | B3: P001-025-002 | C3: GABBIA SUP.DQS 100/125 | D3: Cilindro | E3: DQS100-125 Ø55 | F3: DQS100 = 87 || DQS125 = 103 | H3: 2 | I3: 16.46 | J3: PTFE modificato* | K3: =(( I3/1000 )*'P001-025-002'!$F$1 + SUM('P001-025-002'!$G$4:'P001-025-002'!$G$30))*H3 -> 0 | L3: m | M3: =150*Tabella1[[#This Row],[Quantità]] -> 300
A4: 3 | B4: P001-024-019B | C4: GABBIA INF. DQS 100/125 | D4: Cilindro | E4: DQS100-125 Ø55 | F4: DQS100/DQS125 = 106 | H4: 2 | I4: 22.28 | J4: PTFE modificato* | K4: =(( I4/1000 )*'P001-024-019B'!$F$1 + SUM('P001-024-019B'!$G$4:'P001-024-019B'!$G$30))*H4 -> 200 | L4: m | M4: =150*Tabella1[[#This Row],[Quantità]] -> 300
A5: 4 | B5: P001-025-003 | C5: TAPPO SUP.CORPO FLUIDO | H5: 2 | I5: 100 | J5: PTFE generico | K5: =(( I5/1000 )*'P001-025-003'!$F$1 + SUM('P001-025-003'!$G$4:'P001-025-003'!$G$30))*H5 -> 0 | L5: m | M5: =150*Tabella1[[#This Row],[Quantità]] -> 300
A6: 5 | B6: P001-024-008B | C6: SEDE SFERA DQS 100/125 | H6: 2 | I6: 3.13 | J6: PTFE modificato* | K6: =(( I6/1000 )*'P001-024-008B'!$F$1 + SUM('P001-024-008B'!$G$4:'P001-024-008B'!$G$30))*H6 -> 0 | L6: m | M6: =150*Tabella1[[#This Row],[Quantità]] -> 300
A7: 6 | B7: SF030 | C7: SFERA ø 30 | H7: 4 | I7: 31 | J7: PTFE generico | K7: =COMM_SF030!$D$4*H7 -> 0 | L7: b | M7: =150*Tabella1[[#This Row],[Quantità]] -> 600
A8: 7 | B8: A001-024-006 | C8: VNR SEGNALE DQS 100/125 | H8: 2 | I8: 1 | L8: b | M8: =150*Tabella1[[#This Row],[Quantità]] -> 300
A9: 7.1 | B9: P001-024-031 | C9: CORPO VNR SEGNALE DQS100/125 | H9: 1 | I9: 0.99 | J9: POM-C | K9: =(( I9/1000 )*'P001-024-031'!$F$1 + SUM('P001-024-031'!$G$4:'P001-024-031'!$G$30))*H9 -> 0 | L9: b | M9: =150*Tabella1[[#This Row],[Quantità]] -> 150
A10: 7.2 | B10: Spina 1 x 6 | C10: SPINA 1 X 4 | H10: 1 | I10: 1 | L10: b | M10: =150*Tabella1[[#This Row],[Quantità]] -> 150
A11: 7.3 | B11: SF1-8 | C11: SFERA 1/8" | H11: 1 | I11: 1 | J11: AISI304 | L11: b | M11: =150*Tabella1[[#This Row],[Quantità]] -> 150
A12: 7.4 | B12: OR2021 | H12: 3 | I12: 1 | L12: b | M12: =150*Tabella1[[#This Row],[Quantità]] -> 450
A13: 8 | B13: A001-024-011 | C13: ELEMENTO DI PASSAGIO ALIM. MEMBRANE | H13: 2 | L13: b | M13: =150*Tabella1[[#This Row],[Quantità]] -> 300
A14: 8.1 | B14: P001-024-052 | C14: CORPO ELEMENTO DI PASSAGIO ALIM. MEMBRANE | H14: 1 | I14: 2.49 | J14: POM-C | K14: =(( I14/1000 )*'P001-024-052'!$F$1 + SUM('P001-024-052'!$G$4:'P001-024-052'!$G$30))*H14 -> 0 | L14: b | M14: =150*Tabella1[[#This Row],[Quantità]] -> 150
A15: 8.2 | B15: OR2043 | H15: 3 | I15: 1 | K15: =COMM_OR2043!$D$4*H15 -> 0 | L15: b | M15: =150*Tabella1[[#This Row],[Quantità]] -> 450
A16: 9 | B16: A001-024-002 | C16: DISTRIBUTORE DQS 100/125 | H16: 1 | I16: 56.67 | L16: m | M16: =150*Tabella1[[#This Row],[Quantità]] -> 150
A17: 9.1 | B17: OR 3100 | H17: 2 | I17: 1 | L17: b | M17: =150*Tabella1[[#This Row],[Quantità]] -> 300
A18: 9.2 | B18: P001-024-028 | C18: TENUTA DISTRIBUTORE DQS100- 125 | H18: 2 | I18: 0.24 | J18: PE UHMW | K18: =(( I18/1000 )*'P001-024-028'!$F$1 + SUM('P001-024-028'!$G$4:'P001-024-028'!$G$30))*H18 -> 0 | L18: b | M18: =150*Tabella1[[#This Row],[Quantità]] -> 300
A19: 9.3 | B19: P001-024-012A | C19: ROCCHETTO DISTRIBUTORE DQS100-125 | H19: 1 | I19: 16.4 | J19: POM-C | K19: =(( I19/1000 )*'P001-024-012A'!$F$1 + SUM('P001-024-012A'!$G$4:'P001-024-012A'!$G$30))*H19 -> 0 | L19: b | M19: =150*Tabella1[[#This Row],[Quantità]] -> 150
A20: 9.4 | B20: P001-024-010A | C20: SPOLA DISTRIBUTORE DQS100- 125 | H20: 1 | I20: 25.12 | J20: POM-C | K20: =(( I20/1000 )*'P001-024-010A'!$F$1 + SUM('P001-024-010A'!$G$4:'P001-024-010A'!$G$30))*H20 -> 0 | L20: b | M20: =150*Tabella1[[#This Row],[Quantità]] -> 150
A21: 9.5 | B21: 941625X19X3J5PO00 | C21: TENUTA A LABBRO DISTRIBUTORE DQS 100-125 | H21: 2 | I21: 0.1 | J21: PU | K21: =COMM_941625X19X3J5PO00!$D$4*H21 -> 0 | L21: b | M21: =150*Tabella1[[#This Row],[Quantità]] -> 300
A22: 9.6 | B22: P001-024-011 | C22: TAPPO DI TESTA DISTRIBUTORE DQS100-125 | H22: 2 | I22: 5.59 | J22: POM-C | K22: =(( I22/1000 )*'P001-024-011'!$F$1 + SUM('P001-024-011'!$G$4:'P001-024-011'!$G$30))*H22 -> 0 | L22: b | M22: =150*Tabella1[[#This Row],[Quantità]] -> 300
A23: 9.7 | B23: OR 2106 | H23: 6 | I23: 1 | L23: b | M23: =150*Tabella1[[#This Row],[Quantità]] -> 900
A24: 10 | B24: P001-024-016 | C24: ANELLO DI ARRESTO DISTRIBUTORE DQS 100/125 | H24: 2 | I24: 1.04 | J24: POM-C | K24: =(( I24/1000 )*'P001-024-016'!$F$1 + SUM('P001-024-016'!$G$4:'P001-024-016'!$G$30))*H24 -> 0 | L24: b | M24: =150*Tabella1[[#This Row],[Quantità]] -> 300
A25: 11 | B25: A001-024-007A | C25: TESTATA LATO SINISTRO | H25: 1 | I25: 2918.18 | L25: m | M25: =150*Tabella1[[#This Row],[Quantità]] -> 150
A26: 11.1 | B26: P001-024-021B | C26: CORPO SX LATO ARIA | H26: 1 | I26: 2316.62 | J26: POM-C | K26: =(( I26/1000 )*'P001-024-021B'!$F$1 + SUM('P001-024-021B'!$G$4:'P001-024-021B'!$G$30))*H26 -> 0 | L26: m | M26: =150*Tabella1[[#This Row],[Quantità]] -> 150
A27: 11.2 | B27: A001-024-005E | C27: CARTUCCIONE DQS100/125 | H27: 1 | I27: 106.83 | L27: m | M27: =150*Tabella1[[#This Row],[Quantità]] -> 150
A28: 11.2.1 | B28: P001-024-022D | C28: CORPO CARTUCCIONE DQS100/125 | H28: 1 | I28: 77.72 | J28: POM-C | K28: =(( I28/1000 )*'P001-024-022D'!$F$1 + SUM('P001-024-022D'!$G$4:'P001-024-022D'!$G$30))*H28 -> 0 | L28: m | M28: =150*Tabella1[[#This Row],[Quantità]] -> 150
A29: 11.2.2 | B29: P001-024-023D | C29: CORPO CARTUCCINO DQS100/125 | H29: 1 | I29: 15.09 | J29: POM generico | K29: =(( I29/1000 )*'P001-024-023D'!$F$1 + SUM('P001-024-023D'!$G$4:'P001-024-023D'!$G$30))*H29 -> 0 | L29: m | M29: =150*Tabella1[[#This Row],[Quantità]] -> 150
A30: 11.2.3 | B30: P001-024-024D | C30: PISPOLO CARTUCCINO DQS100/125 | H30: 1 | I30: 3.47 | J30: POM generico | K30: =(( I30/1000 )*'P001-024-024D'!$F$1 + SUM('P001-024-024D'!$G$4:'P001-024-024D'!$G$30))*H30 -> 0 | L30: m | M30: =150*Tabella1[[#This Row],[Quantità]] -> 150
A31: 11.2.4 | B31: C0975-074-0875S D20 | C31: MOLLA DI TENUTA | H31: 1 | I31: 0.89 | J31: AISI 302 | L31: b | M31: =150*Tabella1[[#This Row],[Quantità]] -> 150
A32: 11.2.5 | B32: SF1-8 | C32: SFERA 1/8" AISI304 | H32: 1 | I32: 0.13 | J32: AISI304 | L32: b | M32: =150*Tabella1[[#This Row],[Quantità]] -> 150
A33: 11.2.6 | B33: VNR5 | C33: VNR5 | H33: 1 | I33: 0.539 | K33: =COMM_VNR5!$D$4*H33 -> 0 | L33: b | M33: =150*Tabella1[[#This Row],[Quantità]] -> 150
A34: 11.2.6.1 | B34: CORPO VNR | C34: CORPO VNR | H34: 1 | I34: 0.521 | J34: Ottone | K34: =(( I34/1000 )*'CORPO VNR'!$F$1 + SUM('CORPO VNR'!$G$4:'CORPO VNR'!$G$30))*H34 -> 0 | L34: b | M34: =150*Tabella1[[#This Row],[Quantità]] -> 150
A35: 11.2.6.2 | B35: SF001J5 | C35: SFERA DIAM 1,5 | H35: 1 | I35: 0.014 | J35: AISI 316L | K35: =COMM_SF001J5!$D$4*H35 -> 0 | L35: b | M35: =150*Tabella1[[#This Row],[Quantità]] -> 150
A36: 11.2.6.3 | B36: ISO 2338 - 1 m6 x 4 - St | C36: SPINA M6x4 | H36: 1 | I36: 0.003 | L36: b | M36: =150*Tabella1[[#This Row],[Quantità]] -> 150
A37: 11.2.7 | B37: OR2081 | H37: 1 | I37: 1 | K37: =COMM_OR2081!$D$4*H37 -> 0 | L37: b | M37: =150*Tabella1[[#This Row],[Quantità]] -> 150
A38: 11.2.8 | B38: OR2087 | H38: 2 | I38: 1 | K38: =COMM_OR2087!$D$4*H38 -> 0 | L38: b | M38: =150*Tabella1[[#This Row],[Quantità]] -> 300
A39: 11.2.9 | B39: P001-024-032 | C39: CORPO D'ARRESTO FINE CORSA PISPOLO | H39: 1 | I39: 0.26 | J39: POM generico | K39: =(( I39/1000 )*'P001-024-032'!$F$1 + SUM('P001-024-032'!$G$4:'P001-024-032'!$G$30))*H39 -> 0 | L39: m | M39: =150*Tabella1[[#This Row],[Quantità]] -> 150
A40: 11.2.10 | B40: OR108 | H40: 1 | I40: 1 | K40: =COMM_OR108!$D$4*H40 -> 0 | M40: =150*Tabella1[[#This Row],[Quantità]] -> 150
...

Sheet P001-025-001B
A1: P001-025-001B | B1: P001-025-001B | C1: CORPO FLUIDO | D1: TEST | E1: Costo materiale [€/kg] | F1: 1000 | H1: ⇦ Torna alla DB
A2: Ultima modifica: 26/09/2025
A3: Fase | B3: Descrizione fase | C3: Tipo | D3: Fornitore | E3: Codice fornitore | F3: Centro | G3: Costo lavorazione [€/pz] | H3: Lead time medio [gg] | I3: Note
A4: 10 | B4: Taglio | C4: Esterna | D4: ce | E4: 51 | F4: 100 (HERMLE C42U) | G4: 5
A5: 20 | B5: Tornitura | C5: Esterna | D5: csdvc | E5: 51 | F5: 100 (HERMLE C42U) | G5: 10
A6: 30 | B6: Fresatura | C6: Interna | D6: csdvc | E6: 24 | F6: 101 (Sigma Compact 5) | G6: 15

Sheet P001-025-002
A1: Num. parte | B1: P001-025-002 | C1: GABBIA SUP.DQS 100/125 | E1: Costo materiale [€/kg] | H1: ⇦ Torna alla DB
A2: Ultima modifica: 26/09/2025
A3: Fase | B3: Descrizione fase | C3: Tipo | D3: Fornitore | E3: Codice fornitore | F3: Centro | G3: Costo lavorazione [€/pz] | H3: Lead time medio [gg] | I3: Note
K9: documetazione
K10: qualita

Sheet P001-024-019B
A1: Num. parte | B1: P001-024-019B | C1: GABBIA INF. DQS 100/125 | E1: Costo materiale [€/kg] | H1: ⇦ Torna alla DB
A2: Ultima modifica: 26/09/2025
A3: Fase | B3: Descrizione fase | C3: Tipo | D3: Fornitore | E3: Codice fornitore | F3: Centro | G3: Costo lavorazione [€/pz] | H3: Lead time medio [gg] | I3: Note
A4: 10 | B4: tornitura | C4: Esterna | D4: argal | E4: 315456153 | F4: Esterna | G4: 100 | H4: 5
A5: 20 | B5: fresatura | C5: Interna
K8: certificato di qualità
K9: 3,1 materiale
K10: step
K11: tavola

Sheet P001-025-003
A1: Num. parte | B1: P001-025-003 | C1: TAPPO SUP.CORPO FLUIDO | E1: Costo materiale [€/kg] | H1: ⇦ Torna alla DB
A2: Ultima modifica: 26/09/2025
A3: Fase | B3: Descrizione fase | C3: Tipo | D3: Fornitore | E3: Codice fornitore | F3: Centro | G3: Costo lavorazione [€/pz] | H3: Lead time medio [gg] | I3: Note
B6: Fresatura 1 parte | C6: Esterna | F6: 101 (Sigma Compact 5)
B7: Fresatura 2 parte | C7: Interna

Sheet P001-024-008B
A1: Num. parte | B1: P001-024-008B | C1: SEDE SFERA DQS 100/125 | E1: Costo materiale [€/kg] | H1: ⇦ Torna alla DB
A2: Ultima modifica: 26/09/2025
A3: Fase | B3: Descrizione fase | C3: Tipo | D3: Fornitore | E3: Codice fornitore | F3: Centro | G3: Costo lavorazione [€/pz] | H3: Lead time medio [gg] | I3: Note

Sheet P001-024-031
A1: Num. parte | B1: P001-024-031 | E1: Costo materiale [€/kg] | H1: ⇦ Torna alla DB
A2: Ultima modifica: 26/09/2025
A3: Fase | B3: Descrizione fase | C3: Tipo | D3: Fornitore | E3: Codice fornitore | F3: Centro | G3: Costo lavorazione [€/pz] | H3: Lead time medio [gg] | I3: Note

Sheet P001-024-052
A1: Num. parte | B1: P001-024-052 | E1: Costo materiale [€/kg] | H1: ⇦ Torna alla DB
A2: Ultima modifica: 26/09/2025
A3: Fase | B3: Descrizione fase | C3: Tipo | D3: Fornitore | E3: Codice fornitore | F3: Centro | G3: Costo lavorazione [€/pz] | H3: Lead time medio [gg] | I3: Note

Sheet P001-024-028
A1: Num. parte | B1: P001-024-028 | E1: Costo materiale [€/kg] | H1: ⇦ Torna alla DB
A2: Ultima modifica: 26/09/2025
A3: Fase | B3: Descrizione fase | C3: Tipo | D3: Fornitore | E3: Codice fornitore | F3: Centro | G3: Costo lavorazione [€/pz] | H3: Lead time medio [gg] | I3: Note

Sheet P001-024-012A
A1: Num. parte | B1: P001-024-012A | E1: Costo materiale [€/kg] | H1: ⇦ Torna alla DB
A2: Ultima modifica: 26/09/2025
A3: Fase | B3: Descrizione fase | C3: Tipo | D3: Fornitore | E3: Codice fornitore | F3: Centro | G3: Costo lavorazione [€/pz] | H3: Lead time medio [gg] | I3: Note

Sheet P001-024-010A
A1: Num. parte | B1: P001-024-010A | E1: Costo materiale [€/kg] | H1: ⇦ Torna alla DB
A2: Ultima modifica: 26/09/2025
A3: Fase | B3: Descrizione fase | C3: Tipo | D3: Fornitore | E3: Codice fornitore | F3: Centro | G3: Costo lavorazione [€/pz] | H3: Lead time medio [gg] | I3: Note

Sheet P001-024-011
A1: Num. parte | B1: P001-024-011 | E1: Costo materiale [€/kg] | H1: ⇦ Torna alla DB
A2: Ultima modifica: 26/09/2025
A3: Fase | B3: Descrizione fase | C3: Tipo | D3: Fornitore | E3: Codice fornitore | F3: Centro | G3: Costo lavorazione [€/pz] | H3: Lead time medio [gg] | I3: Note

Sheet P001-024-016
A1: Num. parte | B1: P001-024-016 | C1: ANELLO DI ARRESTO DISTRIBUTORE DQS 100/125 | E1: Costo materiale [€/kg] | H1: ⇦ Torna alla DB
A2: Ultima modifica: 26/09/2025
A3: Fase | B3: Descrizione fase | C3: Tipo | D3: Fornitore | E3: Codice fornitore | F3: Centro | G3: Costo lavorazione [€/pz] | H3: Lead time medio [gg] | I3: Note

Sheet P001-024-021B
A1: Num. parte | B1: P001-024-021B | E1: Costo materiale [€/kg] | H1: ⇦ Torna alla DB
A2: Ultima modifica: 26/09/2025
A3: Fase | B3: Descrizione fase | C3: Tipo | D3: Fornitore | E3: Codice fornitore | F3: Centro | G3: Costo lavorazione [€/pz] | H3: Lead time medio [gg] | I3: Note

Sheet P001-024-022D
A1: Num. parte | B1: P001-024-022D | E1: Costo materiale [€/kg] | H1: ⇦ Torna alla DB
A2: Ultima modifica: 26/09/2025
A3: Fase | B3: Descrizione fase | C3: Tipo | D3: Fornitore | E3: Codice fornitore | F3: Centro | G3: Costo lavorazione [€/pz] | H3: Lead time medio [gg] | I3: Note

Sheet P001-024-023D
A1: Num. parte | B1: P001-024-023D | E1: Costo materiale [€/kg] | H1: ⇦ Torna alla DB
A2: Ultima modifica: 26/09/2025
A3: Fase | B3: Descrizione fase | C3: Tipo | D3: Fornitore | E3: Codice fornitore | F3: Centro | G3: Costo lavorazione [€/pz] | H3: Lead time medio [gg] | I3: Note

Sheet P001-024-024D
A1: Num. parte | B1: P001-024-024D | E1: Costo materiale [€/kg] | H1: ⇦ Torna alla DB
A2: Ultima modifica: 26/09/2025
A3: Fase | B3: Descrizione fase | C3: Tipo | D3: Fornitore | E3: Codice fornitore | F3: Centro | G3: Costo lavorazione [€/pz] | H3: Lead time medio [gg] | I3: Note

Sheet C0975-074-0875S _x000a_D20
A1: Num. parte | B1: C0975-074-0875S D20 | E1: Costo materiale [€/kg] | H1: ⇦ Torna alla DB
A2: Compila i campi per la parte commerciale
A3: Descrizione | B3: Fornitore | C3: Codice fornitore | D3: Prezzo [€/pz] | E3: Lotto minimo riordino [pz] | F3: Lead time medio [gg] | G3: Note

Sheet CORPO VNR
A1: Num. parte | B1: CORPO VNR | E1: Costo materiale [€/kg] | H1: ⇦ Torna alla DB
A2: Ultima modifica: 26/09/2025
A3: Fase | B3: Descrizione fase | C3: Tipo | D3: Fornitore | E3: Codice fornitore | F3: Centro | G3: Costo lavorazione [€/pz] | H3: Lead time medio [gg] | I3: Note

Sheet ISO 2338 - 1 m6 x _x000a_4 - St
A1: Num. parte | B1: ISO 2338 - 1 m6 x 4 - St | E1: Costo materiale [€/kg] | H1: ⇦ Torna alla DB
A2: Ultima modifica: 26/09/2025
A3: Fase | B3: Descrizione fase | C3: Tipo | D3: Fornitore | E3: Codice fornitore | F3: Centro | G3: Costo lavorazione [€/pz] | H3: Lead time medio [gg] | I3: Note

Sheet P001-024-032
A1: Num. parte | B1: P001-024-032 | E1: Costo materiale [€/kg] | H1: ⇦ Torna alla DB
A2: Ultima modifica: 26/09/2025
A3: Fase | B3: Descrizione fase | C3: Tipo | D3: Fornitore | E3: Codice fornitore | F3: Centro | G3: Costo lavorazione [€/pz] | H3: Lead time medio [gg] | I3: Note

Sheet P001-024-037
A1: Num. parte | B1: P001-024-037 | E1: Costo materiale [€/kg] | H1: ⇦ Torna alla DB
A2: Ultima modifica: 26/09/2025
A3: Fase | B3: Descrizione fase | C3: Tipo | D3: Fornitore | E3: Codice fornitore | F3: Centro | G3: Costo lavorazione [€/pz] | H3: Lead time medio [gg] | I3: Note

Sheet P001-024-035
A1: Num. parte | B1: P001-024-035 | E1: Costo materiale [€/kg] | H1: ⇦ Torna alla DB
A2: Ultima modifica: 26/09/2025
A3: Fase | B3: Descrizione fase | C3: Tipo | D3: Fornitore | E3: Codice fornitore | F3: Centro | G3: Costo lavorazione [€/pz] | H3: Lead time medio [gg] | I3: Note

Sheet P001-024-036
A1: Num. parte | B1: P001-024-036 | E1: Costo materiale [€/kg] | H1: ⇦ Torna alla DB
A2: Ultima modifica: 26/09/2025
A3: Fase | B3: Descrizione fase | C3: Tipo | D3: Fornitore | E3: Codice fornitore | F3: Centro | G3: Costo lavorazione [€/pz] | H3: Lead time medio [gg] | I3: Note

Sheet P001-024-025B
A1: Num. parte | B1: P001-024-025B | E1: Costo materiale [€/kg] | H1: ⇦ Torna alla DB
A2: Ultima modifica: 26/09/2025
A3: Fase | B3: Descrizione fase | C3: Tipo | D3: Fornitore | E3: Codice fornitore | F3: Centro | G3: Costo lavorazione [€/pz] | H3: Lead time medio [gg] | I3: Note

Sheet P001-024-026
A1: Num. parte | B1: P001-024-026 | E1: Costo materiale [€/kg] | H1: ⇦ Torna alla DB
A2: Ultima modifica: 26/09/2025
A3: Fase | B3: Descrizione fase | C3: Tipo | D3: Fornitore | E3: Codice fornitore | F3: Centro | G3: Costo lavorazione [€/pz] | H3: Lead time medio [gg] | I3: Note

Sheet P001-024-042
A1: Num. parte | B1: P001-024-042 | E1: Costo materiale [€/kg] | H1: ⇦ Torna alla DB
A2: Ultima modifica: 26/09/2025
A3: Fase | B3: Descrizione fase | C3: Tipo | D3: Fornitore | E3: Codice fornitore | F3: Centro | G3: Costo lavorazione [€/pz] | H3: Lead time medio [gg] | I3: Note

Sheet P001-024-041A
A1: Num. parte | B1: P001-024-041A | E1: Costo materiale [€/kg] | H1: ⇦ Torna alla DB
A2: Ultima modifica: 26/09/2025
A3: Fase | B3: Descrizione fase | C3: Tipo | D3: Fornitore | E3: Codice fornitore | F3: Centro | G3: Costo lavorazione [€/pz] | H3: Lead time medio [gg] | I3: Note

Sheet P001-024-043
A1: Num. parte | B1: P001-024-043 | E1: Costo materiale [€/kg] | H1: ⇦ Torna alla DB
A2: Ultima modifica: 26/09/2025
A3: Fase | B3: Descrizione fase | C3: Tipo | D3: Fornitore | E3: Codice fornitore | F3: Centro | G3: Costo lavorazione [€/pz] | H3: Lead time medio [gg] | I3: Note

Sheet P001-024-044
A1: Num. parte | B1: P001-024-044 | E1: Costo materiale [€/kg] | H1: ⇦ Torna alla DB
A2: Ultima modifica: 26/09/2025
A3: Fase | B3: Descrizione fase | C3: Tipo | D3: Fornitore | E3: Codice fornitore | F3: Centro | G3: Costo lavorazione [€/pz] | H3: Lead time medio [gg] | I3: Note

Sheet P001-024-045
A1: Num. parte | B1: P001-024-045 | E1: Costo materiale [€/kg] | H1: ⇦ Torna alla DB
A2: Ultima modifica: 26/09/2025
A3: Fase | B3: Descrizione fase | C3: Tipo | D3: Fornitore | E3: Codice fornitore | F3: Centro | G3: Costo lavorazione [€/pz] | H3: Lead time medio [gg] | I3: Note

Sheet P001-024-054
A1: Num. parte | B1: P001-024-054 | E1: Costo materiale [€/kg] | H1: ⇦ Torna alla DB
A2: Ultima modifica: 26/09/2025
A3: Fase | B3: Descrizione fase | C3: Tipo | D3: Fornitore | E3: Codice fornitore | F3: Centro | G3: Costo lavorazione [€/pz] | H3: Lead time medio [gg] | I3: Note

Sheet P001-024-002B
A1: Num. parte | B1: P001-024-002B | C1: BOCCOLA GUIDA ALBERO | E1: Costo materiale [€/kg] | H1: ⇦ Torna alla DB
A2: Ultima modifica: 26/09/2025
A3: Fase | B3: Descrizione fase | C3: Tipo | D3: Fornitore | E3: Codice fornitore | F3: Centro | G3: Costo lavorazione [€/pz] | H3: Lead time medio [gg] | I3: Note

Sheet P001-024-004
A1: Num. parte | B1: P001-024-004 | C1: ALBERO DQS 100/125 | E1: Costo materiale [€/kg] | H1: ⇦ Torna alla DB
A2: Ultima modifica: 26/09/2025
A3: Fase | B3: Descrizione fase | C3: Tipo | D3: Fornitore | E3: Codice fornitore | F3: Centro | G3: Costo lavorazione [€/pz] | H3: Lead time medio [gg] | I3: Note

Sheet P001-024-005
A1: Num. parte | B1: P001-024-005 | C1: CAPPELLOTTO DQS 100/125 | E1: Costo materiale [€/kg] | H1: ⇦ Torna alla DB
A2: Ultima modifica: 26/09/2025
A3: Fase | B3: Descrizione fase | C3: Tipo | D3: Fornitore | E3: Codice fornitore | F3: Centro | G3: Costo lavorazione [€/pz] | H3: Lead time medio [gg] | I3: Note

Sheet 375923KE00
A1: Num. parte | B1: 375923KE00 | C1: MEMBRANA DI BACKUP PER POMPA QT 160 | E1: Costo materiale [€/kg] | H1: ⇦ Torna alla DB
A2: Ultima modifica: 26/09/2025
A3: Fase | B3: Descrizione fase | C3: Tipo | D3: Fornitore | E3: Codice fornitore | F3: Centro | G3: Costo lavorazione [€/pz] | H3: Lead time medio [gg] | I3: Note

Sheet P001-024-038
A1: Num. parte | B1: P001-024-038 | C1: MEMBRANA LATO FLUIDO PER POMPA QT 160 | E1: Costo materiale [€/kg] | H1: ⇦ Torna alla DB
A2: Ultima modifica: 26/09/2025
A3: Fase | B3: Descrizione fase | C3: Tipo | D3: Fornitore | E3: Codice fornitore | F3: Centro | G3: Costo lavorazione [€/pz] | H3: Lead time medio [gg] | I3: Note

Sheet P001-024-015C
A1: Num. parte | B1: P001-024-015C | E1: Costo materiale [€/kg] | H1: ⇦ Torna alla DB
A2: Ultima modifica: 26/09/2025
A3: Fase | B3: Descrizione fase | C3: Tipo | D3: Fornitore | E3: Codice fornitore | F3: Centro | G3: Costo lavorazione [€/pz] | H3: Lead time medio [gg] | I3: Note

Sheet Foglio2

Sheet P001-025-008KOREA
A1: Num. parte | B1: P001-025-008KOREA | E1: Costo materiale [€/kg] | H1: ⇦ Torna alla DB
A2: Ultima modifica: 26/09/2025
A3: Fase | B3: Descrizione fase | C3: Tipo | D3: Fornitore | E3: Codice fornitore | F3: Centro | G3: Costo lavorazione [€/pz] | H3: Lead time medio [gg] | I3: Note

Sheet P001-024-046
A1: Num. parte | B1: P001-024-046 | E1: Costo materiale [€/kg] | H1: ⇦ Torna alla DB
A2: Ultima modifica: 26/09/2025
A3: Fase | B3: Descrizione fase | C3: Tipo | D3: Fornitore | E3: Codice fornitore | F3: Centro | G3: Costo lavorazione [€/pz] | H3: Lead time medio [gg] | I3: Note

Sheet P001-024-047
A1: Num. parte | B1: P001-024-047 | E1: Costo materiale [€/kg] | H1: ⇦ Torna alla DB
A2: Ultima modifica: 26/09/2025
A3: Fase | B3: Descrizione fase | C3: Tipo | D3: Fornitore | E3: Codice fornitore | F3: Centro | G3: Costo lavorazione [€/pz] | H3: Lead time medio [gg] | I3: Note

Sheet P001-025-009KOREA
A1: Num. parte | B1: P001-025-009KOREA | E1: Costo materiale [€/kg] | H1: ⇦ Torna alla DB
A2: Ultima modifica: 26/09/2025
A3: Fase | B3: Descrizione fase | C3: Tipo | D3: Fornitore | E3: Codice fornitore | F3: Centro | G3: Costo lavorazione [€/pz] | H3: Lead time medio [gg] | I3: Note

Sheet RST M8x3
A1: Num. parte | B1: RST M8x3 | E1: Costo materiale [€/kg] | H1: ⇦ Torna alla DB
A2: Ultima modifica: 26/09/2025
A3: Fase | B3: Descrizione fase | C3: Tipo | D3: Fornitore | E3: Codice fornitore | F3: Centro | G3: Costo lavorazione [€/pz] | H3: Lead time medio [gg] | I3: Note

Sheet P001-024-050
A1: Num. parte | B1: P001-024-050 | E1: Costo materiale [€/kg] | H1: ⇦ Torna alla DB
A2: Ultima modifica: 26/09/2025
A3: Fase | B3: Descrizione fase | C3: Tipo | D3: Fornitore | E3: Codice fornitore | F3: Centro | G3: Costo lavorazione [€/pz] | H3: Lead time medio [gg] | I3: Note

Sheet P001-024-051
A1: Num. parte | B1: P001-024-051 | E1: Costo materiale [€/kg] | H1: ⇦ Torna alla DB
A2: Ultima modifica: 26/09/2025
A3: Fase | B3: Descrizione fase | C3: Tipo | D3: Fornitore | E3: Codice fornitore | F3: Centro | G3: Costo lavorazione [€/pz] | H3: Lead time medio [gg] | I3: Note

Sheet 9TTP40J6PELD
A1: Num. parte | B1: 9TTP40J6PELD | C1: TAPPO 40,6 | E1: Costo materiale [€/kg] | H1: ⇦ Torna alla DB
A2: Ultima modifica: 26/09/2025
A3: Fase | B3: Descrizione fase | C3: Tipo | D3: Fornitore | E3: Codice fornitore | F3: Centro | G3: Costo lavorazione [€/pz] | H3: Lead time medio [gg] | I3: Note

Sheet 9TTP25J5PELD
A1: Num. parte | B1: 9TTP25J5PELD | C1: TAPPO 25,5 | E1: Costo materiale [€/kg] | H1: ⇦ Torna alla DB
A2: Ultima modifica: 26/09/2025
A3: Fase | B3: Descrizione fase | C3: Tipo | D3: Fornitore | E3: Codice fornitore | F3: Centro | G3: Costo lavorazione [€/pz] | H3: Lead time medio [gg] | I3: Note

Sheet P001-024-039
A1: Num. Parte | B1: P001-024-039 | E1: Costo materiale [€/kg] | H1: ⇦ Torna alla DB
A2: Ultima modifica: 26/09/2025
A3: Fase | B3: Descrizione fase | C3: Tipo | D3: Fornitore | E3: Codice fornitore | F3: Centro | G3: Costo lavorazione [€/pz] | H3: Lead time medio [gg] | I3: Note

Sheet P001-025-004
A1: Num. parte | B1: P001-025-004 | E1: Costo materiale [€/kg] | H1: ⇦ Torna alla DB
A2: Ultima modifica: 26/09/2025
A3: Fase | B3: Descrizione fase | C3: Tipo | D3: Fornitore | E3: Codice fornitore | F3: Centro | G3: Costo lavorazione [€/pz] | H3: Lead time medio [gg] | I3: Note

Sheet P001-025-007
A1: Num. parte | B1: P001-025-007 | C1: ISOLA SCRITTURA MATRICOLA DQS 100/125 | E1: Costo materiale [€/kg] | H1: ⇦ Torna alla DB
A2: Ultima modifica: 26/09/2025
A3: Fase | B3: Descrizione fase | C3: Tipo | D3: Fornitore | E3: Codice fornitore | F3: Centro | G3: Costo lavorazione [€/pz] | H3: Lead time medio [gg] | I3: Note

Sheet PM012216E
A1: Num. parte | B1: PM012216E | C1: RACCORDO JG 1/2" X 12 | E1: Costo materiale [€/kg] | H1: ⇦ Torna alla DB
A2: Ultima modifica: 26/09/2025
A3: Fase | B3: Descrizione fase | C3: Tipo | D3: Fornitore | E3: Codice fornitore | F3: Centro | G3: Costo lavorazione [€/pz] | H3: Lead time medio [gg] | I3: Note

Sheet COMM_SF030
A1: Num. Parte | B1: SF030 | G1: ⇦ Torna alla DB
A2: Compila i campi per la parte commerciale
A3: Descrizione | B3: Fornitore | C3: Codice fornitore | D3: Prezzo [€/pz] | E3: Lotto minimo riordino [pz] | F3: Lead time medio [gg] | G3: Note
A4: SFERA ø 30 -- PTFE generico

Sheet COMM_A001-024-006
A1: Num. parte | B1: A001-024-006 | G1: ⇦ Torna alla DB
A2: Compila i campi per la parte commerciale
A3: Descrizione | B3: Fornitore | C3: Codice fornitore | D3: Prezzo [€/pz] | E3: Lotto minimo riordino [pz] | F3: Lead time medio [gg] | G3: Note
A4: VNR SEGNALE DQS 100/125

Sheet COMM_spina_1_x_6
A1: Num. Parte | B1: spina 1 x 6 | G1: ⇦ Torna alla DB
A2: Compila i campi per la parte commerciale
A3: Descrizione | B3: Fornitore | C3: Codice fornitore | D3: Prezzo [€/pz] | E3: Lotto minimo riordino [pz] | F3: Lead time medio [gg] | G3: Note
A4: SPINA 1 X 4 | D4: 150

Sheet COMM_SF1-8
A1: Num. parte | B1: SF1-8 | G1: ⇦ Torna alla DB
A2: Compila i campi per la parte commerciale
A3: Descrizione | B3: Fornitore | C3: Codice fornitore | D3: Prezzo [€/pz] | E3: Lotto minimo riordino [pz] | F3: Lead time medio [gg] | G3: Note
A4: SFERA 1/8" AISI304 -- AISI304

Sheet COMM_OR2021
A1: Num. parte | B1: OR2021 | G1: ⇦ Torna alla DB
A2: Compila i campi per la parte commerciale
A3: Descrizione | B3: Fornitore | C3: Codice fornitore | D3: Prezzo [€/pz] | E3: Lotto minimo riordino [pz] | F3: Lead time medio [gg] | G3: Note

Sheet COMM_A001-024-011
A1: Num. parte | B1: A001-024-011 | G1: ⇦ Torna alla DB
A2: Compila i campi per la parte commerciale
A3: Descrizione | B3: Fornitore | C3: Codice fornitore | D3: Prezzo [€/pz] | E3: Lotto minimo riordino [pz] | F3: Lead time medio [gg] | G3: Note
A4: ELEMENTO DI PASSAGIO ALIM. MEMBRANE

Sheet COMM_OR2043
A1: Num. parte | B1: OR2043 | G1: ⇦ Torna alla DB
A2: Compila i campi per la parte commerciale
A3: Descrizione | B3: Fornitore | C3: Codice fornitore | D3: Prezzo [€/pz] | E3: Lotto minimo riordino [pz] | F3: Lead time medio [gg] | G3: Note

Sheet COMM_A001-024-002
A1: Num. parte | B1: A001-024-002 | G1: ⇦ Torna alla DB
A2: Compila i campi per la parte commerciale
A3: Descrizione | B3: Fornitore | C3: Codice fornitore | D3: Prezzo [€/pz] | E3: Lotto minimo riordino [pz] | F3: Lead time medio [gg] | G3: Note
A4: DISTRIBUTORE DQS 100/125

Sheet COMM_or_3100
A1: Num. parte | B1: or 3100 | G1: ⇦ Torna alla DB
A2: Compila i campi per la parte commerciale
A3: Descrizione | B3: Fornitore | C3: Codice fornitore | D3: Prezzo [€/pz] | E3: Lotto minimo riordino [pz] | F3: Lead time medio [gg] | G3: Note
D4: 100

Sheet COMM_941625X19X3J5PO00
A1: Num. parte | B1: 941625X19X3J5PO00 | G1: ⇦ Torna alla DB
A2: Compila i campi per la parte commerciale
A3: Descrizione | B3: Fornitore | C3: Codice fornitore | D3: Prezzo [€/pz] | E3: Lotto minimo riordino [pz] | F3: Lead time medio [gg] | G3: Note
A4: TENUTA A LABBRO DISTRIBUTORE DQS 100-125 -- PU

Sheet COMM_or_2106
A1: Num. parte | B1: or 2106 | G1: ⇦ Torna alla DB
A2: Compila i campi per la parte commerciale
A3: Descrizione | B3: Fornitore | C3: Codice fornitore | D3: Prezzo [€/pz] | E3: Lotto minimo riordino [pz] | F3: Lead time medio [gg] | G3: Note

Sheet COMM_A001-024-007A
A1: Num. parte | B1: A001-024-007A | G1: ⇦ Torna alla DB
A2: Compila i campi per la parte commerciale
A3: Descrizione | B3: Fornitore | C3: Codice fornitore | D3: Prezzo [€/pz] | E3: Lotto minimo riordino [pz] | F3: Lead time medio [gg] | G3: Note
A4: TESTATA LATO SINISTRO

Sheet COMM_A001-024-005E
A1: Num. parte | B1: A001-024-005E | G1: ⇦ Torna alla DB
A2: Compila i campi per la parte commerciale
A3: Descrizione | B3: Fornitore | C3: Codice fornitore | D3: Prezzo [€/pz] | E3: Lotto minimo riordino [pz] | F3: Lead time medio [gg] | G3: Note
A4: CARTUCCIONE DQS100/125

Sheet COMM_VNR5
A1: Num. parte | B1: VNR5 | G1: ⇦ Torna alla DB
A2: Compila i campi per la parte commerciale
A3: Descrizione | B3: Fornitore | C3: Codice fornitore | D3: Prezzo [€/pz] | E3: Lotto minimo riordino [pz] | F3: Lead time medio [gg] | G3: Note
A4: VNR5

Sheet COMM_SF001J5
A1: Num. parte | B1: SF001J5 | G1: ⇦ Torna alla DB
A2: Compila i campi per la parte commerciale
A3: Descrizione | B3: Fornitore | C3: Codice fornitore | D3: Prezzo [€/pz] | E3: Lotto minimo riordino [pz] | F3: Lead time medio [gg] | G3: Note
A4: SFERA DIAM 1,5 -- AISI 316L

Sheet COMM_OR2081
A1: Num. parte | B1: OR2081 | G1: ⇦ Torna alla DB
A2: Compila i campi per la parte commerciale
A3: Descrizione | B3: Fornitore | C3: Codice fornitore | D3: Prezzo [€/pz] | E3: Lotto minimo riordino [pz] | F3: Lead time medio [gg] | G3: Note

Sheet COMM_OR2087
A1: Num. parte | B1: OR2087 | G1: ⇦ Torna alla DB
A2: Compila i campi per la parte commerciale
A3: Descrizione | B3: Fornitore | C3: Codice fornitore | D3: Prezzo [€/pz] | E3: Lotto minimo riordino [pz] | F3: Lead time medio [gg] | G3: Note

Sheet COMM_OR108
A1: Num. parte | B1: OR108 | G1: ⇦ Torna alla DB
A2: Compila i campi per la parte commerciale
A3: Descrizione | B3: Fornitore | C3: Codice fornitore | D3: Prezzo [€/pz] | E3: Lotto minimo riordino [pz] | F3: Lead time medio [gg] | G3: Note

Sheet COMM_OR2187
A1: Num. parte | B1: OR2187 | G1: ⇦ Torna alla DB
A2: Compila i campi per la parte commerciale
A3: Descrizione | B3: Fornitore | C3: Codice fornitore | D3: Prezzo [€/pz] | E3: Lotto minimo riordino [pz] | F3: Lead time medio [gg] | G3: Note

Sheet COMM_OR2031
A1: Num. parte | B1: OR2031 | G1: ⇦ Torna alla DB
A2: Compila i campi per la parte commerciale
A3: Descrizione | B3: Fornitore | C3: Codice fornitore | D3: Prezzo [€/pz] | E3: Lotto minimo riordino [pz] | F3: Lead time medio [gg] | G3: Note

Sheet COMM_SF3-32
A1: Num. parte | B1: SF3-32 | G1: ⇦ Torna alla DB
A2: Compila i campi per la parte commerciale
A3: Descrizione | B3: Fornitore | C3: Codice fornitore | D3: Prezzo [€/pz] | E3: Lotto minimo riordino [pz] | F3: Lead time medio [gg] | G3: Note
A4: SFERA TAPPO CARTUCCINO -- AISI 304

Sheet COMM_OR3118
A1: Num. parte | B1: OR3118 | G1: ⇦ Torna alla DB
A2: Compila i campi per la parte commerciale
A3: Descrizione | B3: Fornitore | C3: Codice fornitore | D3: Prezzo [€/pz] | E3: Lotto minimo riordino [pz] | F3: Lead time medio [gg] | G3: Note

Sheet COMM_OR4287
A1: Num. parte | B1: OR4287 | G1: ⇦ Torna alla DB
A2: Compila i campi per la parte commerciale
A3: Descrizione | B3: Fornitore | C3: Codice fornitore | D3: Prezzo [€/pz] | E3: Lotto minimo riordino [pz] | F3: Lead time medio [gg] | G3: Note

Sheet COMM_OR3200
A1: Num. parte | B1: OR3200 | G1: ⇦ Torna alla DB
A2: Compila i campi per la parte commerciale
A3: Descrizione | B3: Fornitore | C3: Codice fornitore | D3: Prezzo [€/pz] | E3: Lotto minimo riordino [pz] | F3: Lead time medio [gg] | G3: Note

Sheet COMM_OR2200
A1: Num. parte | B1: OR2200 | G1: ⇦ Torna alla DB
A2: Compila i campi per la parte commerciale
A3: Descrizione | B3: Fornitore | C3: Codice fornitore | D3: Prezzo [€/pz] | E3: Lotto minimo riordino [pz] | F3: Lead time medio [gg] | G3: Note

Sheet COMM_A001-024-003C
A1: Num. parte | B1: A001-024-003C | G1: ⇦ Torna alla DB
A2: Compila i campi per la parte commerciale
A3: Descrizione | B3: Fornitore | C3: Codice fornitore | D3: Prezzo [€/pz] | E3: Lotto minimo riordino [pz] | F3: Lead time medio [gg] | G3: Note
A4: TESTATA LATO DESTRO

Sheet COMM_A001-025-003KOREA
A1: Num. parte | B1: A001-025-003KOREA | G1: ⇦ Torna alla DB
A2: Compila i campi per la parte commerciale
A3: Descrizione | B3: Fornitore | C3: Codice fornitore | D3: Prezzo [€/pz] | E3: Lotto minimo riordino [pz] | F3: Lead time medio [gg] | G3: Note
A4: ASSIEME TIRANTE ANCORAGGIO DQS 100/125

Sheet COMM_A001-024-009
A1: Num. parte | B1: A001-024-009 | G1: ⇦ Torna alla DB
A2: Compila i campi per la parte commerciale
A3: Descrizione | B3: Fornitore | C3: Codice fornitore | D3: Prezzo [€/pz] | E3: Lotto minimo riordino [pz] | F3: Lead time medio [gg] | G3: Note
A4: TAPPO TIRANTE FLANGIATO -- ETFE / PP- GF30 / PVDF- CFF15

Sheet COMM_A001-024-010
A1: Num. parte | B1: A001-024-010 | G1: ⇦ Torna alla DB
A2: Compila i campi per la parte commerciale
A3: Descrizione | B3: Fornitore | C3: Codice fornitore | D3: Prezzo [€/pz] | E3: Lotto minimo riordino [pz] | F3: Lead time medio [gg] | G3: Note
A4: ASSIEME TIRANTE CORPO POMPA DQS 100/125

Sheet COMM_Dado_cieco_M8_DIN__1587
A1: Num. parte | B1: Dado_cieco_M8_DIN__1587 | G1: ⇦ Torna alla DB
A2: Compila i campi per la parte commerciale
A3: Descrizione | B3: Fornitore | C3: Codice fornitore | D3: Prezzo [€/pz] | E3: Lotto minimo riordino [pz] | F3: Lead time medio [gg] | G3: Note
A4: Dado cieco M8 DIN 1587 -- AISI 316L

Sheet COMM_DADO_FLANGIATO__M8
A1: Num. parte | B1: DADO_FLANGIATO__M8 | G1: ⇦ Torna alla DB
A2: Compila i campi per la parte commerciale
A3: Descrizione | B3: Fornitore | C3: Codice fornitore | D3: Prezzo [€/pz] | E3: Lotto minimo riordino [pz] | F3: Lead time medio [gg] | G3: Note
A4: DADO FLANGIATO M8 -- AISI 316L

Sheet COMM_A001-025-002KOREA
A1: Num. parte | B1: A001-025-002KOREA | G1: ⇦ Torna alla DB
A2: Compila i campi per la parte commerciale
A3: Descrizione | B3: Fornitore | C3: Codice fornitore | D3: Prezzo [€/pz] | E3: Lotto minimo riordino [pz] | F3: Lead time medio [gg] | G3: Note
A4: ASSIEME BASE ANCORAGGIO DQS 100/125

Sheet COMM_OR4061
A1: Num. parte | B1: OR4061 | G1: ⇦ Torna alla DB
A2: Compila i campi per la parte commerciale
A3: Descrizione | B3: Fornitore | C3: Codice fornitore | D3: Prezzo [€/pz] | E3: Lotto minimo riordino [pz] | F3: Lead time medio [gg] | G3: Note
A4: OR4061 3,53 X 15,47
